File: NdH_90_5_133gpa.txt
#Acq. time (s)=	5
#Accumulations=	1
#Range (cm-¹)=	1300...1750
#Windows=	1
#Autofocus=	Off
#AutoExposure=	Off
#Spike filter=	Single accum. (Size=3)
#Delay time (s)=	1
#Binning=	1
#Readout mode=	Signal
#DeNoise=	Standard
#ICS correction=	On
#Dark correction=	Off
#Inst. Process=	Off
#Instrument=	LabRAM HR Evol
#Detector=	Synapse
#Objective=	x20SLWD
#Grating=	600 gr/mm
#ND Filter=	10%
#Laser (nm)=	633
#Hole=	150.001
#Range=	Visible
#Collection=	Microscope
#StageXY=	Marzhauser
#StageZ=	Marzhauser
#X (µm)=	0
#Y (µm)=	0
#Z (µm)=	0
#Project=	20190124
#Sample=	1-2
#Site=
#Title=	D_980
#Remark=
#Date=	05.04.2019 07:24
#Acquired=	05.04.2019 07:24:57
1300.32	45.2604
1301.4	30.7277
1302.49	33.4432
1303.58	34.1156
1304.67	34.6688
1305.76	34.8583
1306.85	35.3577
1307.94	35.5285
1309.02	35.6378
1310.11	35.6567
1311.2	35.6024
1312.29	35.4736
1313.37	35.3041
1314.46	35.1361
1315.55	34.9659
1316.63	34.8363
1317.72	34.7832
1318.81	34.7937
1319.89	35.0098
1320.98	34.9472
1322.06	35.0778
1323.15	35.1237
1324.23	35.784
1325.32	36.0036
1326.4	36.4772
1327.49	36.8117
1328.57	37.4692
1329.66	38.4168
1330.74	39.6944
1331.83	41.2989
1332.91	43.2198
1334	45.474
1335.08	49.4703
1336.16	54.6461
1337.24	64.9141
1338.33	85.2046
1339.41	114.432
1340.49	160.067
1341.58	203.982
1342.66	235.331
1343.74	244.709
1344.82	239.41
1345.91	226.925
1346.99	216.585
1348.07	206.117
1349.15	196.602
1350.23	191.31
1351.31	189.854
1352.39	174.928
1353.47	171.124
1354.55	165.722
1355.64	160.493
1356.72	156.025
1357.8	151.891
1358.88	148.03
1359.95	144.452
1361.03	141.054
1362.11	137.753
1363.19	134.451
1364.27	131.303
1365.35	128.457
1366.43	125.511
1367.51	122.608
1368.59	119.707
1369.66	116.918
1370.74	114.299
1371.82	111.874
1372.9	109.629
1373.98	107.575
1375.05	105.691
1376.13	103.76
1377.21	101.976
1378.28	100.351
1379.36	98.7642
1380.44	97.0632
1381.51	95.401
1382.59	93.6781
1383.67	91.8487
1384.74	90.2143
1385.82	88.9325
1386.89	87.6993
1387.97	86.509
1389.04	85.329
1390.12	84.1154
1391.19	82.9127
1392.27	81.6359
1393.34	80.7813
1394.42	79.8985
1395.49	78.9967
1396.56	78.1321
1397.64	77.335
1398.71	76.613
1399.78	75.9871
1400.86	75.469
1401.93	75.0419
1403	74.6388
1404.08	73.8596
1405.15	73.1454
1406.22	72.4258
1407.29	71.7737
1408.37	71.242
1409.44	70.4821
1410.51	70.0049
1411.58	69.3459
1412.65	68.6349
1413.72	67.6832
1414.79	66.831
1415.87	66.0595
1416.94	65.4591
1418.01	65.0486
1419.08	64.8007
1420.15	64.633
1421.22	64.7459
1422.29	64.6125
1423.36	64.3343
1424.43	63.9675
1425.5	63.1193
1426.56	62.6453
1427.63	62.2508
1428.7	62.0225
1429.77	62.0114
1430.84	62.0796
1431.91	61.9516
1432.98	61.5507
1434.04	60.9689
1435.11	60.275
1436.18	59.5017
1437.25	59.028
1438.31	58.5315
1439.38	58.4554
1440.45	57.9405
1441.51	57.3562
1442.58	56.8327
1443.65	56.3333
1444.71	55.953
1445.78	55.8664
1446.85	55.6856
1447.91	55.7908
1448.98	55.7847
1450.04	55.6919
1451.11	55.7716
1452.17	56.2361
1453.24	56.475
1454.3	56.6614
1455.37	56.6982
1456.43	56.7181
1457.5	56.3481
1458.56	56.1949
1459.62	55.975
1460.69	55.8042
1461.75	55.5822
1462.82	55.347
1463.88	55.1162
1464.94	54.9405
1466	54.7076
1467.07	54.474
1468.13	54.441
1469.19	54.012
1470.25	53.4722
1471.32	53.1385
1472.38	52.7481
1473.44	52.4636
1474.5	52.1934
1475.56	51.924
1476.62	51.6786
1477.69	51.6502
1478.75	51.6948
1479.81	51.7764
1480.87	52.0187
1481.93	51.9603
1482.99	51.8317
1484.05	51.8811
1485.11	51.921
1486.17	51.7898
1487.23	51.5061
1488.29	50.6453
1489.35	50.6326
1490.41	50.6944
1491.47	50.8407
1492.52	51.3274
1493.58	51.5998
1494.64	52.0493
1495.7	52.4375
1496.76	52.4173
1497.82	52.4502
1498.87	51.978
1499.93	51.5218
1500.99	51.063
1502.05	51.1127
1503.1	51.1153
1504.16	50.9827
1505.21	50.6555
1506.27	50.4254
1507.33	50.2356
1508.38	50.0491
1509.44	49.8024
1510.5	49.4957
1511.55	49.1917
1512.61	48.7859
1513.66	48.1982
1514.72	48.1957
1515.77	48.2613
1516.83	48.5233
1517.88	48.4527
1518.94	48.4076
1519.99	48.3827
1521.05	48.3673
1522.1	48.3602
1523.15	48.3456
1524.21	48.2688
1525.26	48.1674
1526.32	47.6533
1527.37	47.5052
1528.42	47.4826
1529.48	47.517
1530.53	47.6325
1531.58	47.8934
1532.63	48.104
1533.69	48.1709
1534.74	48.2338
1535.79	48.2938
1536.84	48.352
1537.89	48.3161
1538.94	48.2527
1540	48.3545
1541.05	48.4695
1542.1	48.6991
1543.15	49.1749
1544.2	49.3489
1545.25	49.3778
1546.3	49.2927
1547.35	49.1469
1548.4	48.9333
1549.45	48.8114
1550.5	48.711
1551.55	48.6329
1552.6	48.2359
1553.65	48.1877
1554.7	48.1795
1555.74	48.2367
1556.79	48.3408
1557.84	48.8332
1558.89	48.9736
1559.94	49.0453
1560.99	49.6488
1562.03	49.6644
1563.08	49.6518
1564.13	49.4867
1565.18	49.3081
1566.22	49.1691
1567.27	49.084
1568.32	49.0412
1569.36	49.0353
1570.41	49.0828
1571.46	49.1914
1572.5	49.3808
1573.55	49.7563
1574.59	50.1316
1575.64	50.5895
1576.69	51.3026
1577.73	52.2399
1578.78	53.1701
1579.82	53.4873
1580.87	54.7152
1581.91	56.8444
1582.96	58.622
1584	61.4066
1585.04	64.6384
1586.09	67.4191
1587.13	68.4395
1588.18	67.8623
1589.22	57.057
1590.26	49.7357
1591.31	41.0467
1592.35	38.0575
1593.39	37.6842
1594.43	35.9343
1595.48	33.7572
1596.52	33.5638
1597.56	33.4176
1598.6	33.2971
1599.65	33.1999
1600.69	33.1185
1601.73	33.055
1602.77	33.0135
1603.81	32.9822
1604.85	32.9611
1605.89	32.9428
1606.93	32.9362
1607.98	32.9316
1609.02	32.9523
1610.06	32.942
1611.1	32.9551
1612.14	32.9431
1613.18	32.9555
1614.22	32.9388
1615.26	32.9458
1616.29	32.9767
1617.33	33.0349
1618.37	32.9917
1619.41	32.9266
1620.45	32.8535
1621.49	32.7715
1622.53	32.6933
1623.57	32.5983
1624.6	32.5177
1625.64	32.412
1626.68	32.3252
1627.72	32.2144
1628.75	32.1325
1629.79	32.0097
1630.83	31.8979
1631.86	31.819
1632.9	31.7344
1633.94	31.6487
1634.97	31.5565
1636.01	31.4566
1637.05	31.4258
1638.08	31.406
1639.12	31.402
1640.15	31.4135
1641.19	31.4403
1642.23	31.4836
1643.26	31.5423
1644.29	31.615
1645.33	31.7484
1646.36	31.8541
1647.4	31.968
1648.43	32.0654
1649.47	32.2392
1650.5	32.3594
1651.53	32.4504
1652.57	32.5672
1653.6	32.6971
1654.63	32.7944
1655.67	32.8819
1656.7	32.9632
1657.73	33.0276
1658.77	33.0906
1659.8	33.1312
1660.83	33.1566
1661.86	33.1185
1662.9	33.0767
1663.93	33.0187
1664.96	32.9998
1665.99	32.951
1667.02	32.8965
1668.05	32.8594
1669.09	32.7828
1670.12	32.7235
1671.15	32.672
1672.18	32.6182
1673.21	32.5653
1674.24	32.5053
1675.27	32.4539
1676.3	32.3959
1677.33	32.3413
1678.36	32.2871
1679.39	32.2402
1680.42	32.1973
1681.45	32.1632
1682.47	32.135
1683.5	32.1117
1684.53	32.0772
1685.56	32.0603
1686.59	32.1318
1687.62	32.0886
1688.64	32.0435
1689.67	31.9891
1690.7	31.9422
1691.73	31.8858
1692.76	31.8329
1693.78	31.7676
1694.81	31.7052
1695.84	31.6368
1696.86	31.5535
1697.89	31.4488
1698.92	31.3437
1699.94	31.286
1700.97	31.2102
1701.99	31.1637
1703.02	31.1018
1704.05	31.0728
1705.07	31.0376
1706.1	31.0289
1707.12	31.0207
1708.15	31.0318
1709.17	31.0493
1710.2	31.0787
1711.22	31.1191
1712.24	31.2865
1713.27	31.3724
1714.29	31.4588
1715.32	31.5645
1716.34	31.6488
1717.36	31.7304
1718.39	31.8189
1719.41	31.9091
1720.43	32.0182
1721.46	32.0938
1722.48	32.1591
1723.5	32.2313
1724.52	32.2914
1725.55	32.3566
1726.57	32.405
1727.59	32.4638
1728.61	32.5038
1729.63	32.5398
1730.65	32.4525
1731.68	32.4451
1732.7	32.4497
1733.72	32.4268
1734.74	32.3971
1735.76	32.3748
1736.78	32.3117
1737.8	32.2764
1738.82	32.238
1739.84	32.2004
1740.86	32.1642
1741.88	32.1323
1742.9	32.0933
1743.92	32.0744
1744.94	32.0406
1745.96	32.0549
1746.98	32.0348
1748	32.1306
1749.02	32.1421